╒═══════════════════╤════════╕
│ run config name   │        │
╞═══════════════════╪════════╡
│ CONFIG_NAME       │ base   │
├───────────────────┼────────┤
│ device            │ cuda   │
├───────────────────┼────────┤
│ epochs            │ 20     │
├───────────────────┼────────┤
│ learning rate     │ 0.0001 │
├───────────────────┼────────┤
│ batch size        │ 16     │
╘═══════════════════╧════════╛
Dataset with 38732 samples across 1 sites.
Starting epoch 1/20.
C:\Users\shafner\AppData\Local\Continuum\anaconda3\envs\local\lib\site-packages\torch\nn\modules\loss.py:528: UserWarning: Using a target size (torch.Size([16])) that is different to the input size (torch.Size([16, 1])). This will likely lead to incorrect results due to broadcasting. Please ensure they have the same size.
  return F.mse_loss(input, target, reduction=self.reduction)
Traceback (most recent call last):
  File "C:/Users/shafner/repos/population_mapping/train_network.py", line 143, in <module>
    run_training(cfg)
  File "C:/Users/shafner/repos/population_mapping/train_network.py", line 62, in run_training
    for i, batch in enumerate(dataloader):
  File "C:\Users\shafner\AppData\Local\Continuum\anaconda3\envs\local\lib\site-packages\torch\utils\data\dataloader.py", line 521, in __next__
    data = self._next_data()
  File "C:\Users\shafner\AppData\Local\Continuum\anaconda3\envs\local\lib\site-packages\torch\utils\data\dataloader.py", line 1183, in _next_data
    return self._process_data(data)
  File "C:\Users\shafner\AppData\Local\Continuum\anaconda3\envs\local\lib\site-packages\torch\utils\data\dataloader.py", line 1229, in _process_data
    data.reraise()
  File "C:\Users\shafner\AppData\Local\Continuum\anaconda3\envs\local\lib\site-packages\torch\_utils.py", line 425, in reraise
    raise self.exc_type(msg)
FileNotFoundError: Caught FileNotFoundError in DataLoader worker process 4.
Original Traceback (most recent call last):
  File "C:\Users\shafner\AppData\Local\Continuum\anaconda3\envs\local\lib\site-packages\torch\utils\data\_utils\worker.py", line 287, in _worker_loop
    data = fetcher.fetch(index)
  File "C:\Users\shafner\AppData\Local\Continuum\anaconda3\envs\local\lib\site-packages\torch\utils\data\_utils\fetch.py", line 44, in fetch
    data = [self.dataset[idx] for idx in possibly_batched_index]
  File "C:\Users\shafner\AppData\Local\Continuum\anaconda3\envs\local\lib\site-packages\torch\utils\data\_utils\fetch.py", line 44, in <listcomp>
    data = [self.dataset[idx] for idx in possibly_batched_index]
  File "C:\Users\shafner\repos\population_mapping\utils\datasets.py", line 103, in __getitem__
    img = self._get_vhr_data(city, patch_id, i, j)
  File "C:\Users\shafner\repos\population_mapping\utils\datasets.py", line 84, in _get_vhr_data
    patch_data = self._get_vhr_patch(city, patch_id)
  File "C:\Users\shafner\repos\population_mapping\utils\datasets.py", line 29, in _get_vhr_patch
    img, _, _ = geofiles.read_tif(file)
  File "C:\Users\shafner\repos\population_mapping\utils\geofiles.py", line 11, in read_tif
    raise FileNotFoundError(f'File {file} not found')
FileNotFoundError: File C:\Users\shafner\datasets\pop_dataset\satellite_data\dakar\vhr_dakar_0000038000-0000028000.tif not found